Workbook

Sheet README
A1: Strategy model: custom packaging business, Kathmandu Valley (NPR). Research cut-off 2026-10-23.
A2: Purpose: decide WHAT to sell, WHERE to source it, and WHICH cost/revenue levers to pull, using Nepal and Indian small-business benchmarks.
A3: Blue = input/assumption; black = formula. Evidence grade in each sheet: V = fetched page, S = search snippet/secondary, A = analyst assumption.
A4: No supplier quotation has been received. Nepal customs duty for HS 4819 and India GST treatment are UNVERIFIED inputs on the Inputs sheet.
A5: Sheets: Inputs > India_Benchmarks > Nepal_Benchmarks > Sourcing_Decision > Offer_Ladder > Strategy_Engine > Strategy_vs_Base > Cost_Levers > Revenue_Levers > Label_Printer_BE > Competitor_Matrix > Priority_Matrix > KPI_Targets > Checks.
A6: Strategy_vs_Base compares against v2 Base case of 08_financial_model.xlsx (values pasted, dated 2026-10-23).

Sheet Inputs
A1: Input | B1: Value | C1: Unit | D1: Source / grade
A2: NPR per 100 INR | B2: 160.15 | C2: NPR | D2: NRB selling 12 Oct 2026 (sharesansar). S/High
A3: India GST paid on domestic online purchase (not recoverable) | B3: 0.12 | C3: ratio | D3: A - UNVERIFIED; GST on paper boxes may differ after 2025 rate changes; formal export invoices may be zero-rated
A4: Freight India->Kathmandu (% of value) | B4: 0.08 | C4: ratio | D4: A - courier/cargo estimate
A5: Nepal customs duty on printed cartons/bags (HS 4819) | B5: 0.15 | C5: ratio | D5: A - UNVERIFIED. Budget 2083/84 cut slabs 11->7 (Himalayan Times); check tariff line
A6: Nepal VAT | B6: 0.13 | C6: ratio | D6: Customsnepal FAQ / udhamsathi. S/Medium
A7: VAT registered? (1 = import & supplier VAT recoverable) | B7: 0 | C7: flag | D7: Decision variable
A8: Share of Nepal supplier spend billed with VAT | B8: 0.6 | C8: ratio | D8: A
A9: Fixed cost per import shipment (clearing agent + documentation + local pickup) | B9: 7000 | C9: NPR | D9: A - UNVERIFIED; get clearing-agent quote
A10: Units per consolidated monthly import shipment | B10: 1000 | C10: units | D10: A - pooling several customers' short runs
A11: Own delivery cost per order (v1 assumption) | B11: 600 | C11: NPR | D11: v1 model Product_Pricing delivery range 400-800
A12: 3PL last-mile cost per delivery | B12: 80 | C12: NPR | D12: Kathmandu Post 27 Aug 2026: Rs70-80 per delivery. S/Medium
A13: Payment/financing cost | B13: 0.015 | C13: % rev | D13: A
... A21: Shadow cost of founder design hour | B21: 400 | C21: NPR/hour | D21: A
A23: Derived: landed-cost multiplier on Indian list price (excl. fixed shipment cost) | B23: =(1+Inputs!$B$3)*(1+Inputs!$B$4)*(1+Inputs!$B$5)*(1+IF(Inputs!$B$7=1,0,Inputs!$B$6)) -> 1.5718752
A24: Derived: Nepal supplier VAT leakage multiplier | B24: =1+(1-Inputs!$B$7)*Inputs!$B$6*Inputs!$B$8 -> 1.078
A25: Derived: fixed import cost per unit when consolidated | B25: =Inputs!$B$9/Inputs!$B$10 -> 7

Sheet India_Benchmarks
A1: Product (Indian small-run supplier) | B1: Supplier | C1: Qty | D1: Price INR/unit | E1: NPR/unit (list) | F1: Landed NPR/unit (consolidated) | G1: Landed NPR/unit (single-customer shipment) | H1: Grade | I1: Source (accessed 2026-10-23)
A2: Flat mailer box, custom printed | B2: Printo | C2: 10 | D2: 30 | E2: =D2*Inputs!$B$2/100 -> 48.045 | F2: =E2*Inputs!$B$23+Inputs!$B$25 -> 82.520744 | G2: =E2*Inputs!$B$23+Inputs!$B$9/C2 -> 775.52074 | H2: V | I2: https://printo.in/categories/shipping-and-flat-mailer-boxes
A3: Single-colour printed mailer | B3: Printo | C3: 50 | D3: 33 | E3: =D3*Inputs!$B$2/100 -> 52.8495 | F3: =E3*Inputs!$B$23+Inputs!$B$25 -> 90.072818 | G3: =E3*Inputs!$B$23+Inputs!$B$9/C3 -> 223.07282 | H3: V | I3: same
A4: Multicolour flat mailer | B4: Printo | C4: 500 | D4: 79 | E4: =D4*Inputs!$B$2/100 -> 126.5185 | F4: =E4*Inputs!$B$23+Inputs!$B$25 -> 205.87129 | G4: =E4*Inputs!$B$23+Inputs!$B$9/C4 -> 212.87129 | H4: V | I4: same
A5: Custom printed mono carton | B5: Printo | C5: 10 | D5: 33 | E5: =D5*Inputs!$B$2/100 -> 52.8495 | F5: =E5*Inputs!$B$23+Inputs!$B$25 -> 90.072818 | G5: =E5*Inputs!$B$23+Inputs!$B$9/C5 -> 783.07282 | H5: V | I5: same
A6: Sticker-embellished mailer (stock box + custom sticker) | B6: Printo | C6: 25 | D6: 33 | E6: =D6*Inputs!$B$2/100 -> 52.8495 | F6: =E6*Inputs!$B$23+Inputs!$B$25 -> 90.072818 | G6: =E6*Inputs!$B$23+Inputs!$B$9/C6 -> 363.07282 | H6: V | I6: same - KEY MODEL TO COPY
A7: Shipping carton | B7: Printo | C7: 100 | D7: 19 | E7: =D7*Inputs!$B$2/100 -> 30.4285 | F7: =E7*Inputs!$B$23+Inputs!$B$25 -> 54.829805 | G7: =E7*Inputs!$B$23+Inputs!$B$9/C7 -> 117.8298 | H7: V | I7: same
A8: Top & bottom rigid box | B8: Printo | C8: 100 | D8: 247 | E8: =D8*Inputs!$B$2/100 -> 395.5705 | F8: =E8*Inputs!$B$23+Inputs!$B$25 -> 628.78746 | G8: =E8*Inputs!$B$23+Inputs!$B$9/C8 -> 691.78746 | H8: V | I8: same
A9: Magnetic flap rigid box | B9: Printo | C9: 100 | D9: 317 | E9: =D9*Inputs!$B$2/100 -> 507.6755 | F9: =E9*Inputs!$B$23+Inputs!$B$25 -> 805.00253 | G9: =E9*Inputs!$B$23+Inputs!$B$9/C9 -> 868.00253 | H9: V | I9: same
A10: Custom packaging, 50-100 pcs (midpoint of 50-120) | B10: EzPac | C10: 100 | D10: 85 | E10: =D10*Inputs!$B$2/100 -> 136.1275 | F10: =E10*Inputs!$B$23+Inputs!$B$25 -> 220.97544 | G10: =E10*Inputs!$B$23+Inputs!$B$9/C10 -> 283.97544 | H10: V | I10: https://ezpac.in/blogs/news/custom-packaging-small-business-india
A11: Custom packaging, 200-500 pcs (midpoint of 30-80) | B11: EzPac | C11: 300 | D11: 55 | E11: =D11*Inputs!$B$2/100 -> 88.0825 | F11: =E11*Inputs!$B$23+Inputs!$B$25 -> 145.4547 | G11: =E11*Inputs!$B$23+Inputs!$B$9/C11 -> 161.78803 | H11: V | I11: same
A12: Custom packaging, 500+ pcs (midpoint of 20-50) | B12: EzPac | C12: 500 | D12: 35 | E12: =D12*Inputs!$B$2/100 -> 56.0525 | F12: =E12*Inputs!$B$23+Inputs!$B$25 -> 95.107535 | G12: =E12*Inputs!$B$23+Inputs!$B$9/C12 -> 102.10753 | H12: V | I12: same
A13: Kraft paper gift bag, logo, MOQ 500 | B13: Mahalaxmi Enterprise (TradeIndia) | C13: 500 | D13: 15 | E13: =D13*Inputs!$B$2/100 -> 24.0225 | F13: =E13*Inputs!$B$23+Inputs!$B$25 -> 44.760372 | G13: =E13*Inputs!$B$23+Inputs!$B$9/C13 -> 51.760372 | H13: S | I13: https://www.tradeindia.com/products/paper-gift-bag-c11491287.html
... A16: Label/sticker (range 1-10, midpoint) | B16: Guide | C16: 1000 | D16: 5.5 | E16: =D16*Inputs!$B$2/100 -> 8.80825 | F16: =E16*Inputs!$B$23+Inputs!$B$25 -> 20.84547 | G16: =E16*Inputs!$B$23+Inputs!$B$9/C16 -> 20.84547 | H16: S | I16: https://www.onlineprintout.in/guides/packaging-printing-for-small-business/
A18: Setup charges (India guide): corrugated die-cut ₹2,000-8,000 per design; rigid box setup ₹5,000-15,000, MOQ ~1,000 offset. Digital short runs 50-100 units carry no die (onlineprintout.in). S
A19: EzPac claims 10-unit MOQ via digital printing, self-serve 3D design studio and live price calculator - removes sales and quoting cost. V
A20: Indian guide cost tips: start with branded labels on plain packaging; use standard sizes (custom die-cut 'doubles setup costs'); consolidate vendors; order Jan-Mar off-peak. V
A21: Printo standard turnaround 20-25 business days; express same-day in selected Indian cities. V
A22: Landed figures use UNVERIFIED duty/GST/fixed-cost inputs. Single-customer shipments are uneconomic; consolidation is the strategy.

Sheet Nepal_Benchmarks
A1: Item | B1: Seller | C1: Price NPR/unit | D1: Basis | E1: Grade | F1: Source
A2: Pastry box (stock) | B2: The Box House Nepal, Thimi | C2: 10 | D2: retail sale price | E2: V | F2: https://boxhousenepal.com.np/
A3: 2 lb corrugated cake box (stock) | B3: The Box House Nepal | C3: 35 | D3: retail sale price | E3: V | F3: same
A4: 12in kraft pizza box (stock) | B4: The Box House Nepal | C4: 20 | D4: retail sale price | E4: V | F4: same
A5: 10in pizza box (stock), per unit from pack of 50 | B5: The Box House Nepal | C5: 24.98 | D5: 1,249 / 50 | E5: V | F5: same
A6: 3PL delivery in Kathmandu | B6: Logistics providers (news) | C6: 80 | D6: per delivery | E6: S | F6: https://kathmandupost.com/money/2026/08/27/fast-delivery-changes-the-game-for-nepal-s-online-sellers
A7: v1 model assumption: folding carton supplier cost @250 | B7: Assumption | C7: 62 | D7: +9,000 setup | E7: A | F7: 07_product_pricing_model.csv
A8: v1 model assumption: mailer supplier cost @250 | B8: Assumption | C8: 64 | D8: +4,000 setup | E8: A | F8: 07
A9: v1 model assumption: kraft bag supplier cost @500 | B9: Assumption | C9: 28 | D9: +2,500 setup | E9: A | F9: 07
A10: v1 model assumption: rigid box supplier cost @100 | B10: Assumption | C10: 350 | D10: +7,000 setup | E10: A | F10: 07
A11: v1 model assumption: sticker 50mm @1000 | B11: Assumption | C11: 3.8 | D11: +500 setup | E11: A | F11: 07
A14: Nepal market signals: 1,530 e-commerce firms applied for registration, 345 approved; Nepal Can Move 1,000+ merchants; Pathao Commerce 600+ merchants in 2 weeks; >90% of online merchants in Kathmandu Valley (Kathmandu Post, 27 Aug 2026). S
A15: 2018 Economic Census establishments: Kathmandu 123,994; Lalitpur 27,009; Bhaktapur 19,629 = 170,632 (all sectors; via stat.go.jp analysis). S

Sheet Sourcing_Decision
A1: Product / run | B1: Qty | C1: Nepal unit cost (A) | D1: Nepal setup (A) | E1: Nepal effective NPR/unit (incl. setup, VAT leak) | F1: India list INR/unit | G1: India landed consolidated NPR/unit | H1: India landed single-shipment NPR/unit | I1: Cheapest option NPR/unit | J1: Decision | K1: Saving vs Nepal per order NPR
A2: Folding carton, short run | B2: 100 | C2: 95 | D2: 9000 | E2: =(C2+D2/B2)*Inputs!$B$24 -> 199.43 | F2: 33 | G2: =F2*Inputs!$B$2/100*Inputs!$B$23+Inputs!$B$25 -> 90.072818 | H2: =F2*Inputs!$B$2/100*Inputs!$B$23+Inputs!$B$9/B2 -> 153.07282 | I2: =MIN(E2,G2) -> 90.072818 | J2: =IF(G2<E2*0.9,"India digital, consolidated",IF(G2<E2,"Marginal - get both quotes","Nepal supplier")) -> India digital, consolidated | K2: =(E2-I2)*B2 -> 10935.718
A3: Folding carton, short run | B3: 250 | C3: 62 | D3: 9000 | E3: =(C3+D3/B3)*Inputs!$B$24 -> 105.644 | F3: 33 | G3: =F3*Inputs!$B$2/100*Inputs!$B$23+Inputs!$B$25 -> 90.072818 | H3: =F3*Inputs!$B$2/100*Inputs!$B$23+Inputs!$B$9/B3 -> 111.07282 | I3: =MIN(E3,G3) -> 90.072818 | J3: =IF(G3<E3*0.9,"India digital, consolidated",IF(G3<E3,"Marginal - get both quotes","Nepal supplier")) -> India digital, consolidated | K3: =(E3-I3)*B3 -> 3892.7954
A4: Folding carton, bulk | B4: 1000 | C4: 30 | D4: 9000 | E4: =(C4+D4/B4)*Inputs!$B$24 -> 42.042 | F4: 33 | G4: =F4*Inputs!$B$2/100*Inputs!$B$23+Inputs!$B$25 -> 90.072818 | H4: =F4*Inputs!$B$2/100*Inputs!$B$23+Inputs!$B$9/B4 -> 90.072818 | I4: =MIN(E4,G4) -> 42.042 | J4: =IF(G4<E4*0.9,"India digital, consolidated",IF(G4<E4,"Marginal - get both quotes","Nepal supplier")) -> Nepal supplier | K4: =(E4-I4)*B4 -> 0
A5: Printed mailer, short run | B5: 100 | C5: 85 | D5: 4000 | E5: =(C5+D5/B5)*Inputs!$B$24 -> 134.75 | F5: 33 | G5: =F5*Inputs!$B$2/100*Inputs!$B$23+Inputs!$B$25 -> 90.072818 | H5: =F5*Inputs!$B$2/100*Inputs!$B$23+Inputs!$B$9/B5 -> 153.07282 | I5: =MIN(E5,G5) -> 90.072818 | J5: =IF(G5<E5*0.9,"India digital, consolidated",IF(G5<E5,"Marginal - get both quotes","Nepal supplier")) -> India digital, consolidated | K5: =(E5-I5)*B5 -> 4467.7182
A6: Printed mailer, mid run | B6: 250 | C6: 64 | D6: 4000 | E6: =(C6+D6/B6)*Inputs!$B$24 -> 86.24 | F6: 33 | G6: =F6*Inputs!$B$2/100*Inputs!$B$23+Inputs!$B$25 -> 90.072818 | H6: =F6*Inputs!$B$2/100*Inputs!$B$23+Inputs!$B$9/B6 -> 111.07282 | I6: =MIN(E6,G6) -> 86.24 | J6: =IF(G6<E6*0.9,"India digital, consolidated",IF(G6<E6,"Marginal - get both quotes","Nepal supplier")) -> Nepal supplier | K6: =(E6-I6)*B6 -> 0
A7: Printed mailer, bulk | B7: 1000 | C7: 40 | D7: 4000 | E7: =(C7+D7/B7)*Inputs!$B$24 -> 47.432 | F7: 33 | G7: =F7*Inputs!$B$2/100*Inputs!$B$23+Inputs!$B$25 -> 90.072818 | H7: =F7*Inputs!$B$2/100*Inputs!$B$23+Inputs!$B$9/B7 -> 90.072818 | I7: =MIN(E7,G7) -> 47.432 | J7: =IF(G7<E7*0.9,"India digital, consolidated",IF(G7<E7,"Marginal - get both quotes","Nepal supplier")) -> Nepal supplier | K7: =(E7-I7)*B7 -> 0
A8: Kraft bag, logo | B8: 500 | C8: 28 | D8: 2500 | E8: =(C8+D8/B8)*Inputs!$B$24 -> 35.574 | F8: 15 | G8: =F8*Inputs!$B$2/100*Inputs!$B$23+Inputs!$B$25 -> 44.760372 | H8: =F8*Inputs!$B$2/100*Inputs!$B$23+Inputs!$B$9/B8 -> 51.760372 | I8: =MIN(E8,G8) -> 35.574 | J8: =IF(G8<E8*0.9,"India digital, consolidated",IF(G8<E8,"Marginal - get both quotes","Nepal supplier")) -> Nepal supplier | K8: =(E8-I8)*B8 -> 0
A9: Kraft bag, logo | B9: 1000 | C9: 23 | D9: 2500 | E9: =(C9+D9/B9)*Inputs!$B$24 -> 27.489 | F9: 15 | G9: =F9*Inputs!$B$2/100*Inputs!$B$23+Inputs!$B$25 -> 44.760372 | H9: =F9*Inputs!$B$2/100*Inputs!$B$23+Inputs!$B$9/B9 -> 44.760372 | I9: =MIN(E9,G9) -> 27.489 | J9: =IF(G9<E9*0.9,"India digital, consolidated",IF(G9<E9,"Marginal - get both quotes","Nepal supplier")) -> Nepal supplier | K9: =(E9-I9)*B9 -> 0
A10: Rigid gift box | B10: 100 | C10: 350 | D10: 7000 | E10: =(C10+D10/B10)*Inputs!$B$24 -> 452.76 | F10: 247 | G10: =F10*Inputs!$B$2/100*Inputs!$B$23+Inputs!$B$25 -> 628.78746 | H10: =F10*Inputs!$B$2/100*Inputs!$B$23+Inputs!$B$9/B10 -> 691.78746 | I10: =MIN(E10,G10) -> 452.76 | J10: =IF(G10<E10*0.9,"India digital, consolidated",IF(G10<E10,"Marginal - get both quotes","Nepal supplier")) -> Nepal supplier | K10: =(E10-I10)*B10 -> 0
A11: Rigid gift box | B11: 250 | C11: 290 | D11: 7000 | E11: =(C11+D11/B11)*Inputs!$B$24 -> 342.804 | F11: 247 | G11: =F11*Inputs!$B$2/100*Inputs!$B$23+Inputs!$B$25 -> 628.78746 | H11: =F11*Inputs!$B$2/100*Inputs!$B$23+Inputs!$B$9/B11 -> 649.78746 | I11: =MIN(E11,G11) -> 342.804 | J11: =IF(G11<E11*0.9,"India digital, consolidated",IF(G11<E11,"Marginal - get both quotes","Nepal supplier")) -> Nepal supplier | K11: =(E11-I11)*B11 -> 0
A12: Sticker 50mm | B12: 1000 | C12: 3.8 | D12: 500 | E12: =(C12+D12/B12)*Inputs!$B$24 -> 4.6354 | F12: 5.5 | G12: =F12*Inputs!$B$2/100*Inputs!$B$23+Inputs!$B$25 -> 20.84547 | H12: =F12*Inputs!$B$2/100*Inputs!$B$23+Inputs!$B$9/B12 -> 20.84547 | I12: =MIN(E12,G12) -> 4.6354 | J12: =IF(G12<E12*0.9,"India digital, consolidated",IF(G12<E12,"Marginal - get both quotes","Nepal supplier")) -> Nepal supplier | K12: =(E12-I12)*B12 -> 0
A13: Sticker 50mm | B13: 5000 | C13: 2.4 | D13: 500 | E13: =(C13+D13/B13)*Inputs!$B$24 -> 2.695 | F13: 5.5 | G13: =F13*Inputs!$B$2/100*Inputs!$B$23+Inputs!$B$25 -> 20.84547 | H13: =F13*Inputs!$B$2/100*Inputs!$B$23+Inputs!$B$9/B13 -> 15.24547 | I13: =MIN(E13,G13) -> 2.695 | J13: =IF(G13<E13*0.9,"India digital, consolidated",IF(G13<E13,"Marginal - get both quotes","Nepal supplier")) -> Nepal supplier | K13: =(E13-I13)*B13 -> 0
A15: Rule derived: runs below ~300 units of printed cartons -> Indian digital printers (no die/plate) pooled into one monthly shipment; bulk runs, bags (bulky, cheap) and rigid boxes -> Nepal suppliers. Re-run with real quotes and verified HS 4819 duty.

Sheet Offer_Ladder
A1: Line (per representative order) | B1: T1 Brand Starter Kit | C1: T2 Short-run Custom | D1: T3 Bulk Custom (brokered) | E1: T4 Design-only package | F1: T5 Packaging Subscription
A2: Description | B2: 100 stock mailers/boxes + 100 custom gang-run stickers + tissue, ready in 3-5 days | C2: 200 digitally printed cartons (India consolidated) or local digital | D2: 1,000 offset mailers/cartons/bags from Nepal factory | E2: Packaging + label design, dieline, mock-up, print-ready files | F2: 300 branded units/month delivered from stock bought in bulk
A3: Units | B3: 100 | C3: 200 | D3: 1000 | E3: 1 | F3: 300
A4: Unit selling price NPR | B4: 80 | C4: 140 | D4: 52 | E4: 8000 | F4: 70
A5: Design / setup fee charged NPR | B5: 1500 | C5: 2000 | D5: 4600 | E5: 0 | F5: 0
A6: Unit product cost NPR | B6: 35 | C6: =Sourcing_Decision!G3 -> 90.072818 | D6: 40 | E6: 0 | F6: 40
A7: Add-on cost per unit (sticker, tissue, storage) NPR | B7: 10 | C7: 0 | D7: 0 | E7: 0 | F7: 4
A8: One-off supplier setup NPR | B8: 0 | C8: 0 | D8: 4000 | E8: 0 | F8: 0
A9: Other direct cost (mock-up print, software share) NPR | B9: 300 | C9: 500 | D9: 500 | E9: 1200 | F9: 0
A10: Revenue (ex-VAT) | B10: =B3*B4+B5 -> 9500 | C10: =C3*C4+C5 -> 30000 | D10: =D3*D4+D5 -> 56600 | E10: =E3*E4+E5 -> 8000 | F10: =F3*F4+F5 -> 21000
A11: Direct cost incl. wastage 3% and Nepal VAT leakage | B11: =(B3*(B6+B7)*1.03+B8)*Inputs!$B$24+B9 -> 5296.53 | C11: =(C3*(C6+C7)*1.03+C8)+C9 -> 19055.001 | D11: =(D3*(D6+D7)*1.03+D8)*Inputs!$B$24+D9 -> 49225.6 | E11: =(E3*(E6+E7)*1.03+E8)+E9 -> 1200 | F11: =(F3*(F6+F7)*1.03+F8)*Inputs!$B$24+F9 -> 14656.488
A12: Gross margin % | B12: =(B10-B11)/B10 -> 0.44247053 | C12: =(C10-C11)/C10 -> 0.36483331 | D12: =(D10-D11)/D10 -> 0.13028975 | E12: =(E10-E11)/E10 -> 0.85 | F12: =(F10-F11)/F10 -> 0.302072
A13: Delivery (3PL) + payment + rework | B13: =Inputs!$B$12+B10*(Inputs!$B$13+Inputs!$B$14) -> 412.5 | C13: =Inputs!$B$12+C10*(Inputs!$B$13+Inputs!$B$14) -> 1130 | D13: =Inputs!$B$12+D10*(Inputs!$B$13+Inputs!$B$14) -> 2061 | E13: =Inputs!$B$12+E10*(Inputs!$B$13+Inputs!$B$14) -> 360 | F13: =Inputs!$B$12+F10*(Inputs!$B$13+Inputs!$B$14) -> 815
A14: Contribution per order | B14: =B10-B11-B13 -> 3790.97 | C14: =C10-C11-C13 -> 9814.9994 | D14: =D10-D11-D13 -> 5313.4 | E14: =E10-E11-E13 -> 6440 | F14: =F10-F11-F13 -> 5528.512
A15: Contribution margin % | B15: =B14/B10 -> 0.39904947 | C15: =C14/C10 -> 0.32716665 | D15: =D14/D10 -> 0.093876325 | E15: =E14/E10 -> 0.805 | F15: =F14/F10 -> 0.26326248
A16: Monthly reorder / retention probability | B16: 0.25 | C16: 0.15 | D16: 0.12 | E16: 0.03 | F16: 0.92
A17: Upfront payment share | B17: 1 | C17: 0.5 | D17: 0.5 | E17: 1 | F17: 1
A19: T1 copies Printo's 'sticker-embellished mailer': stock box + custom sticker gives a branded look without die or plate costs. T1 stock cost uses Box House 2lb cake-box retail price (NPR 35) as a proxy (V).
A20: T2 product cost links to Sourcing_Decision (India digital, consolidated, short-run carton). T3 uses Nepal offset with die; die kept for reorders (standard-size library).

Sheet Strategy_Engine
A1: NPR | B1: M1 | C1: M2 | D1: M3 | E1: M4 | F1: M5 | G1: M6 | H1: M7 | I1: M8 | J1: M9 | K1: M10 | L1: M11 | M1: M12 | N1: 12-mo
A2: T1 Brand Starter Kit
A3: New customers (input x multiplier) | B3: =B4*Inputs!$B$20 -> 0 | C3: =C4*Inputs!$B$20 -> 1.5 | D3: =D4*Inputs!$B$20 -> 2.25 | E3: =E4*Inputs!$B$20 -> 3 | F3: =F4*Inputs!$B$20 -> 3 | G3: =G4*Inputs!$B$20 -> 3.75 | H3: =H4*Inputs!$B$20 -> 3.75 | I3: =I4*Inputs!$B$20 -> 4.5 | ... M3: =M4*Inputs!$B$20 -> 5.25 | N3: =SUM(B3:M3) -> 41.25
A4: Base new-customer plan (input) | B4: 0 | C4: 2 | D4: 3 | E4: 4 | F4: 4 | G4: 5 | H4: 5 | I4: 6 | J4: 6 | K4: 6 | L4: 7 | M4: 7
A5: Active customers at start of month | B5: 0 | C5: =SUM($B3:B3) -> 0 | D5: =SUM($B3:C3) -> 1.5 | E5: =SUM($B3:D3) -> 3.75 | F5: =SUM($B3:E3) -> 6.75 | G5: =SUM($B3:F3) -> 9.75 | H5: =SUM($B3:G3) -> 13.5 | I5: =SUM($B3:H3) -> 17.25 | J5: =SUM($B3:I3) -> 21.75 | ... M5: =SUM($B3:L3) -> 36
A6: Orders | B6: =B3+B5*Offer_Ladder!$B$16 -> 0 | C6: =C3+C5*Offer_Ladder!$B$16 -> 1.5 | D6: =D3+D5*Offer_Ladder!$B$16 -> 2.625 | E6: =E3+E5*Offer_Ladder!$B$16 -> 3.9375 | F6: =F3+F5*Offer_Ladder!$B$16 -> 4.6875 | G6: =G3+G5*Offer_Ladder!$B$16 -> 6.1875 | H6: =H3+H5*Offer_Ladder!$B$16 -> 7.125 | I6: =I3+I5*Offer_Ladder!$B$16 -> 8.8125 | ... M6: =M3+M5*Offer_Ladder!$B$16 -> 14.25 | N6: =SUM(B6:M6) -> 83.0625
A7: Revenue | B7: =B6*Offer_Ladder!$B$10 -> 0 | C7: =C6*Offer_Ladder!$B$10 -> 14250 | D7: =D6*Offer_Ladder!$B$10 -> 24937.5 | E7: =E6*Offer_Ladder!$B$10 -> 37406.25 | F7: =F6*Offer_Ladder!$B$10 -> 44531.25 | G7: =G6*Offer_Ladder!$B$10 -> 58781.25 | H7: =H6*Offer_Ladder!$B$10 -> 67687.5 | I7: =I6*Offer_Ladder!$B$10 -> 83718.75 | ... M7: =M6*Offer_Ladder!$B$10 -> 135375 | N7: =SUM(B7:M7) -> 789093.75
A8: Contribution | B8: =B6*Offer_Ladder!$B$14-B7*Inputs!$B$16*Inputs!$B$15 -> 0 | C8: =C6*Offer_Ladder!$B$14-C7*Inputs!$B$16*Inputs!$B$15 -> 5472.705 | D8: =D6*Offer_Ladder!$B$14-D7*Inputs!$B$16*Inputs!$B$15 -> 9577.2337 | E8: =E6*Offer_Ladder!$B$14-E7*Inputs!$B$16*Inputs!$B$15 -> 14365.851 | F8: =F6*Offer_Ladder!$B$14-F7*Inputs!$B$16*Inputs!$B$15 -> 17102.203 | G8: =G6*Offer_Ladder!$B$14-G7*Inputs!$B$16*Inputs!$B$15 -> 22574.908 | H8: =H6*Offer_Ladder!$B$14-H7*Inputs!$B$16*Inputs!$B$15 -> 25995.349 | I8: =I6*Offer_Ladder!$B$14-I7*Inputs!$B$16*Inputs!$B$15 -> 32152.142 | ... M8: =M6*Offer_Ladder!$B$14-M7*Inputs!$B$16*Inputs!$B$15 -> 51990.698 | N8: =SUM(B8:M8) -> 303051.04
A9: Cash received | B9: =Offer_Ladder!$B$17*B7 -> 0 | C9: =Offer_Ladder!$B$17*C7+(1-Offer_Ladder!$B$17)*B7 -> 14250 | D9: =Offer_Ladder!$B$17*D7+(1-Offer_Ladder!$B$17)*C7 -> 24937.5 | E9: =Offer_Ladder!$B$17*E7+(1-Offer_Ladder!$B$17)*D7 -> 37406.25 | F9: =Offer_Ladder!$B$17*F7+(1-Offer_Ladder!$B$17)*E7 -> 44531.25 | G9: =Offer_Ladder!$B$17*G7+(1-Offer_Ladder!$B$17)*F7 -> 58781.25 | H9: =Offer_Ladder!$B$17*H7+(1-Offer_Ladder!$B$17)*G7 -> 67687.5 | I9: =Offer_Ladder!$B$17*I7+(1-Offer_Ladder!$B$17)*H7 -> 83718.75 | J9: =Offer_Ladder!$B$17*J7+(1-Offer_Ladder!$B$17)*I7 -> 94406.25 | ... M9: =Offer_Ladder!$B$17*M7+(1-Offer_Ladder!$B$17)*L7 -> 135375 | N9: =SUM(B9:M9) -> 789093.75
A10: Direct cost + delivery paid | B10: =B7-B8 -> 0 | C10: =C7-C8 -> 8777.295 | D10: =D7-D8 -> 15360.266 | E10: =E7-E8 -> 23040.399 | F10: =F7-F8 -> 27429.047 | G10: =G7-G8 -> 36206.342 | H10: =H7-H8 -> 41692.151 | I10: =I7-I8 -> 51566.608 | ... M10: =M7-M8 -> 83384.303 | N10: =SUM(B10:M10) -> 486042.71
A12: T2 Short-run Custom
A13: New customers (input x multiplier) | B13: =B14*Inputs!$B$20 -> 0 | C13: =C14*Inputs!$B$20 -> 0.75 | D13: =D14*Inputs!$B$20 -> 0.75 | E13: =E14*Inputs!$B$20 -> 0.75 | F13: =F14*Inputs!$B$20 -> 1.5 | G13: =G14*Inputs!$B$20 -> 1.5 | H13: =H14*Inputs!$B$20 -> 1.5 | I13: =I14*Inputs!$B$20 -> 1.5 | ... M13: =M14*Inputs!$B$20 -> 2.25 | N13: =SUM(B13:M13) -> 17.25
A14: Base new-customer plan (input) | B14: 0 | C14: 1 | D14: 1 | E14: 1 | F14: 2 | G14: 2 | H14: 2 | I14: 2 | J14: 3 | K14: 3 | L14: 3 | M14: 3
A15: Active customers at start of month | B15: 0 | C15: =SUM($B13:B13) -> 0 | D15: =SUM($B13:C13) -> 0.75 | E15: =SUM($B13:D13) -> 1.5 | F15: =SUM($B13:E13) -> 2.25 | G15: =SUM($B13:F13) -> 3.75 | H15: =SUM($B13:G13) -> 5.25 | I15: =SUM($B13:H13) -> 6.75 | J15: =SUM($B13:I13) -> 8.25 | ... M15: =SUM($B13:L13) -> 15
A16: Orders | B16: =B13+B15*Offer_Ladder!$C$16 -> 0 | C16: =C13+C15*Offer_Ladder!$C$16 -> 0.75 | D16: =D13+D15*Offer_Ladder!$C$16 -> 0.8625 | E16: =E13+E15*Offer_Ladder!$C$16 -> 0.975 | F16: =F13+F15*Offer_Ladder!$C$16 -> 1.8375 | G16: =G13+G15*Offer_Ladder!$C$16 -> 2.0625 | H16: =H13+H15*Offer_Ladder!$C$16 -> 2.2875 | I16: =I13+I15*Offer_Ladder!$C$16 -> 2.5125 | ... M16: =M13+M15*Offer_Ladder!$C$16 -> 4.5 | N16: =SUM(B16:M16) -> 27.2625
A17: Revenue | B17: =B16*Offer_Ladder!$C$10 -> 0 | C17: =C16*Offer_Ladder!$C$10 -> 22500 | D17: =D16*Offer_Ladder!$C$10 -> 25875 | E17: =E16*Offer_Ladder!$C$10 -> 29250 | F17: =F16*Offer_Ladder!$C$10 -> 55125 | G17: =G16*Offer_Ladder!$C$10 -> 61875 | H17: =H16*Offer_Ladder!$C$10 -> 68625 | I17: =I16*Offer_Ladder!$C$10 -> 75375 | ... M17: =M16*Offer_Ladder!$C$10 -> 135000 | N17: =SUM(B17:M17) -> 817875
A18: Contribution | B18: =B16*Offer_Ladder!$C$14-B17*Inputs!$B$16*Inputs!$B$15 -> 0 | C18: =C16*Offer_Ladder!$C$14-C17*Inputs!$B$16*Inputs!$B$15 -> 7023.7496 | D18: =D16*Offer_Ladder!$C$14-D17*Inputs!$B$16*Inputs!$B$15 -> 8077.312 | E18: =E16*Offer_Ladder!$C$14-E17*Inputs!$B$16*Inputs!$B$15 -> 9130.8744 | F18: =F16*Offer_Ladder!$C$14-F17*Inputs!$B$16*Inputs!$B$15 -> 17208.186 | G18: =G16*Offer_Ladder!$C$14-G17*Inputs!$B$16*Inputs!$B$15 -> 19315.311 | H18: =H16*Offer_Ladder!$C$14-H17*Inputs!$B$16*Inputs!$B$15 -> 21422.436 | I18: =I16*Offer_Ladder!$C$14-I17*Inputs!$B$16*Inputs!$B$15 -> 23529.561 | ... M18: =M16*Offer_Ladder!$C$14-M17*Inputs!$B$16*Inputs!$B$15 -> 42142.497 | N18: =SUM(B18:M18) -> 255313.3
A19: Cash received | B19: =Offer_Ladder!$C$17*B17 -> 0 | C19: =Offer_Ladder!$C$17*C17+(1-Offer_Ladder!$C$17)*B17 -> 11250 | D19: =Offer_Ladder!$C$17*D17+(1-Offer_Ladder!$C$17)*C17 -> 24187.5 | E19: =Offer_Ladder!$C$17*E17+(1-Offer_Ladder!$C$17)*D17 -> 27562.5 | F19: =Offer_Ladder!$C$17*F17+(1-Offer_Ladder!$C$17)*E17 -> 42187.5 | G19: =Offer_Ladder!$C$17*G17+(1-Offer_Ladder!$C$17)*F17 -> 58500 | H19: =Offer_Ladder!$C$17*H17+(1-Offer_Ladder!$C$17)*G17 -> 65250 | I19: =Offer_Ladder!$C$17*I17+(1-Offer_Ladder!$C$17)*H17 -> 72000 | J19: =Offer_Ladder!$C$17*J17+(1-Offer_Ladder!$C$17)*I17 -> 90000 | ... M19: =Offer_Ladder!$C$17*M17+(1-Offer_Ladder!$C$17)*L17 -> 129937.5 | N19: =SUM(B19:M19) -> 750375
A20: Direct cost + delivery paid | B20: =B17-B18 -> 0 | C20: =C17-C18 -> 15476.25 | D20: =D17-D18 -> 17797.688 | E20: =E17-E18 -> 20119.126 | F20: =F17-F18 -> 37916.814 | G20: =G17-G18 -> 42559.689 | H20: =H17-H18 -> 47202.564 | I20: =I17-I18 -> 51845.439 | ... M20: =M17-M18 -> 92857.503 | N20: =SUM(B20:M20) -> 562561.7
A22: T3 Bulk Custom (brokered)
A23: New customers (input x multiplier) | B23: =B24*Inputs!$B$20 -> 0 | C23: =C24*Inputs!$B$20 -> 0 | D23: =D24*Inputs!$B$20 -> 0 | E23: =E24*Inputs!$B$20 -> 0.75 | F23: =F24*Inputs!$B$20 -> 0 | G23: =G24*Inputs!$B$20 -> 0.75 | H23: =H24*Inputs!$B$20 -> 0 | I23: =I24*Inputs!$B$20 -> 0.75 | ... M23: =M24*Inputs!$B$20 -> 0.75 | N23: =SUM(B23:M23) -> 4.5
A24: Base new-customer plan (input) | B24: 0 | C24: 0 | D24: 0 | E24: 1 | F24: 0 | G24: 1 | H24: 0 | I24: 1 | J24: 1 | K24: 0 | L24: 1 | M24: 1
A25: Active customers at start of month | B25: 0 | C25: =SUM($B23:B23) -> 0 | D25: =SUM($B23:C23) -> 0 | E25: =SUM($B23:D23) -> 0 | F25: =SUM($B23:E23) -> 0.75 | G25: =SUM($B23:F23) -> 0.75 | H25: =SUM($B23:G23) -> 1.5 | I25: =SUM($B23:H23) -> 1.5 | J25: =SUM($B23:I23) -> 2.25 | ... M25: =SUM($B23:L23) -> 3.75
A26: Orders | B26: =B23+B25*Offer_Ladder!$D$16 -> 0 | C26: =C23+C25*Offer_Ladder!$D$16 -> 0 | D26: =D23+D25*Offer_Ladder!$D$16 -> 0 | E26: =E23+E25*Offer_Ladder!$D$16 -> 0.75 | F26: =F23+F25*Offer_Ladder!$D$16 -> 0.09 | G26: =G23+G25*Offer_Ladder!$D$16 -> 0.84 | H26: =H23+H25*Offer_Ladder!$D$16 -> 0.18 | I26: =I23+I25*Offer_Ladder!$D$16 -> 0.93 | ... M26: =M23+M25*Offer_Ladder!$D$16 -> 1.2 | N26: =SUM(B26:M26) -> 6.48
A27: Revenue | B27: =B26*Offer_Ladder!$D$10 -> 0 | C27: =C26*Offer_Ladder!$D$10 -> 0 | D27: =D26*Offer_Ladder!$D$10 -> 0 | E27: =E26*Offer_Ladder!$D$10 -> 42450 | F27: =F26*Offer_Ladder!$D$10 -> 5094 | G27: =G26*Offer_Ladder!$D$10 -> 47544 | H27: =H26*Offer_Ladder!$D$10 -> 10188 | I27: =I26*Offer_Ladder!$D$10 -> 52638 | ... M27: =M26*Offer_Ladder!$D$10 -> 67920 | N27: =SUM(B27:M27) -> 366768
A28: Contribution | B28: =B26*Offer_Ladder!$D$14-B27*Inputs!$B$16*Inputs!$B$15 -> 0 | C28: =C26*Offer_Ladder!$D$14-C27*Inputs!$B$16*Inputs!$B$15 -> 0 | D28: =D26*Offer_Ladder!$D$14-D27*Inputs!$B$16*Inputs!$B$15 -> 0 | E28: =E26*Offer_Ladder!$D$14-E27*Inputs!$B$16*Inputs!$B$15 -> 3348.3 | F28: =F26*Offer_Ladder!$D$14-F27*Inputs!$B$16*Inputs!$B$15 -> 401.796 | G28: =G26*Offer_Ladder!$D$14-G27*Inputs!$B$16*Inputs!$B$15 -> 3750.096 | H28: =H26*Offer_Ladder!$D$14-H27*Inputs!$B$16*Inputs!$B$15 -> 803.592 | I28: =I26*Offer_Ladder!$D$14-I27*Inputs!$B$16*Inputs!$B$15 -> 4151.892 | ... M28: =M26*Offer_Ladder!$D$14-M27*Inputs!$B$16*Inputs!$B$15 -> 5357.28 | N28: =SUM(B28:M28) -> 28929.312
A29: Cash received | B29: =Offer_Ladder!$D$17*B27 -> 0 | C29: =Offer_Ladder!$D$17*C27+(1-Offer_Ladder!$D$17)*B27 -> 0 | D29: =Offer_Ladder!$D$17*D27+(1-Offer_Ladder!$D$17)*C27 -> 0 | E29: =Offer_Ladder!$D$17*E27+(1-Offer_Ladder!$D$17)*D27 -> 21225 | F29: =Offer_Ladder!$D$17*F27+(1-Offer_Ladder!$D$17)*E27 -> 23772 | G29: =Offer_Ladder!$D$17*G27+(1-Offer_Ladder!$D$17)*F27 -> 26319 | H29: =Offer_Ladder!$D$17*H27+(1-Offer_Ladder!$D$17)*G27 -> 28866 | I29: =Offer_Ladder!$D$17*I27+(1-Offer_Ladder!$D$17)*H27 -> 31413 | J29: =Offer_Ladder!$D$17*J27+(1-Offer_Ladder!$D$17)*I27 -> 55185 | ... M29: =Offer_Ladder!$D$17*M27+(1-Offer_Ladder!$D$17)*L27 -> 65373 | N29: =SUM(B29:M29) -> 332808
A30: Direct cost + delivery paid | B30: =B27-B28 -> 0 | C30: =C27-C28 -> 0 | D30: =D27-D28 -> 0 | E30: =E27-E28 -> 39101.7 | F30: =F27-F28 -> 4692.204 | G30: =G27-G28 -> 43793.904 | H30: =H27-H28 -> 9384.408 | I30: =I27-I28 -> 48486.108 | ... M30: =M27-M28 -> 62562.72 | N30: =SUM(B30:M30) -> 337838.69
A32: T4 Design-only package
A33: New customers (input x multiplier) | B33: =B34*Inputs!$B$20 -> 0.75 | C33: =C34*Inputs!$B$20 -> 0.75 | D33: =D34*Inputs!$B$20 -> 0.75 | E33: =E34*Inputs!$B$20 -> 0.75 | F33: =F34*Inputs!$B$20 -> 0.75 | G33: =G34*Inputs!$B$20 -> 0.75 | H33: =H34*Inputs!$B$20 -> 0.75 | I33: =I34*Inputs!$B$20 -> 0.75 | ... M33: =M34*Inputs!$B$20 -> 0.75 | N33: =SUM(B33:M33) -> 9
A34: Base new-customer plan (input) | B34: 1 | C34: 1 | D34: 1 | E34: 1 | F34: 1 | G34: 1 | H34: 1 | I34: 1 | J34: 1 | K34: 1 | L34: 1 | M34: 1
A35: Active customers at start of month | B35: 0 | C35: =SUM($B33:B33) -> 0.75 | D35: =SUM($B33:C33) -> 1.5 | E35: =SUM($B33:D33) -> 2.25 | F35: =SUM($B33:E33) -> 3 | G35: =SUM($B33:F33) -> 3.75 | H35: =SUM($B33:G33) -> 4.5 | I35: =SUM($B33:H33) -> 5.25 | J35: =SUM($B33:I33) -> 6 | ... M35: =SUM($B33:L33) -> 8.25
A36: Orders | B36: =B33+B35*Offer_Ladder!$E$16 -> 0.75 | C36: =C33+C35*Offer_Ladder!$E$16 -> 0.7725 | D36: =D33+D35*Offer_Ladder!$E$16 -> 0.795 | E36: =E33+E35*Offer_Ladder!$E$16 -> 0.8175 | F36: =F33+F35*Offer_Ladder!$E$16 -> 0.84 | G36: =G33+G35*Offer_Ladder!$E$16 -> 0.8625 | H36: =H33+H35*Offer_Ladder!$E$16 -> 0.885 | I36: =I33+I35*Offer_Ladder!$E$16 -> 0.9075 | ... M36: =M33+M35*Offer_Ladder!$E$16 -> 0.9975 | N36: =SUM(B36:M36) -> 10.485
A37: Revenue | B37: =B36*Offer_Ladder!$E$10 -> 6000 | C37: =C36*Offer_Ladder!$E$10 -> 6180 | D37: =D36*Offer_Ladder!$E$10 -> 6360 | E37: =E36*Offer_Ladder!$E$10 -> 6540 | F37: =F36*Offer_Ladder!$E$10 -> 6720 | G37: =G36*Offer_Ladder!$E$10 -> 6900 | H37: =H36*Offer_Ladder!$E$10 -> 7080 | I37: =I36*Offer_Ladder!$E$10 -> 7260 | ... M37: =M36*Offer_Ladder!$E$10 -> 7980 | N37: =SUM(B37:M37) -> 83880
A38: Contribution | B38: =B36*Offer_Ladder!$E$14-B37*Inputs!$B$16*Inputs!$B$15 -> 4740 | C38: =C36*Offer_Ladder!$E$14-C37*Inputs!$B$16*Inputs!$B$15 -> 4882.2 | D38: =D36*Offer_Ladder!$E$14-D37*Inputs!$B$16*Inputs!$B$15 -> 5024.4 | E38: =E36*Offer_Ladder!$E$14-E37*Inputs!$B$16*Inputs!$B$15 -> 5166.6 | F38: =F36*Offer_Ladder!$E$14-F37*Inputs!$B$16*Inputs!$B$15 -> 5308.8 | G38: =G36*Offer_Ladder!$E$14-G37*Inputs!$B$16*Inputs!$B$15 -> 5451 | H38: =H36*Offer_Ladder!$E$14-H37*Inputs!$B$16*Inputs!$B$15 -> 5593.2 | I38: =I36*Offer_Ladder!$E$14-I37*Inputs!$B$16*Inputs!$B$15 -> 5735.4 | ... M38: =M36*Offer_Ladder!$E$14-M37*Inputs!$B$16*Inputs!$B$15 -> 6304.2 | N38: =SUM(B38:M38) -> 66265.2
A39: Cash received | B39: =Offer_Ladder!$E$17*B37 -> 6000 | C39: =Offer_Ladder!$E$17*C37+(1-Offer_Ladder!$E$17)*B37 -> 6180 | D39: =Offer_Ladder!$E$17*D37+(1-Offer_Ladder!$E$17)*C37 -> 6360 | E39: =Offer_Ladder!$E$17*E37+(1-Offer_Ladder!$E$17)*D37 -> 6540 | F39: =Offer_Ladder!$E$17*F37+(1-Offer_Ladder!$E$17)*E37 -> 6720 | G39: =Offer_Ladder!$E$17*G37+(1-Offer_Ladder!$E$17)*F37 -> 6900 | H39: =Offer_Ladder!$E$17*H37+(1-Offer_Ladder!$E$17)*G37 -> 7080 | I39: =Offer_Ladder!$E$17*I37+(1-Offer_Ladder!$E$17)*H37 -> 7260 | J39: =Offer_Ladder!$E$17*J37+(1-Offer_Ladder!$E$17)*I37 -> 7440 | ... M39: =Offer_Ladder!$E$17*M37+(1-Offer_Ladder!$E$17)*L37 -> 7980 | N39: =SUM(B39:M39) -> 83880
A40: Direct cost + delivery paid | B40: =B37-B38 -> 1260 | C40: =C37-C38 -> 1297.8 | D40: =D37-D38 -> 1335.6 | E40: =E37-E38 -> 1373.4 | F40: =F37-F38 -> 1411.2 | G40: =G37-G38 -> 1449 | H40: =H37-H38 -> 1486.8 | I40: =I37-I38 -> 1524.6 | ... M40: =M37-M38 -> 1675.8 | N40: =SUM(B40:M40) -> 17614.8
A42: T5 Packaging Subscription
A43: New customers (input x multiplier) | B43: =B44*Inputs!$B$20 -> 0 | C43: =C44*Inputs!$B$20 -> 0 | D43: =D44*Inputs!$B$20 -> 0 | E43: =E44*Inputs!$B$20 -> 0 | F43: =F44*Inputs!$B$20 -> 0.75 | G43: =G44*Inputs!$B$20 -> 0 | H43: =H44*Inputs!$B$20 -> 0.75 | I43: =I44*Inputs!$B$20 -> 0 | ... M43: =M44*Inputs!$B$20 -> 0 | N43: =SUM(B43:M43) -> 3
A44: Base new-customer plan (input) | B44: 0 | C44: 0 | D44: 0 | E44: 0 | F44: 1 | G44: 0 | H44: 1 | I44: 0 | J44: 1 | K44: 0 | L44: 1 | M44: 0
...

Sheet Capital_Plan
A1: Line (strategy launch, NPR) | B1: Amount | C1: Change vs 08 Config B
A2: Refurbished laptop | B2: 55000 | C2: same
A3: Design software 12 months | B3: 15000 | C3: same
A4: Hand tools & finishing kit | B4: 20000 | C4: -10,000: no powered tools; cutting mats, creasing, guillotine A3
A5: Furniture & storage | B5: 5000 | C5: -10,000: home office first 4 months
A6: Premises deposit | B6: 0 | C6: -25,000: defer until >=15 active customers
A7: Standard stock inventory (boxes/bags in 4-6 standard sizes) + sticker media | B7: 40000 | C7: NEW: enables T1 Starter Kit, 3-5 day delivery
A8: Sample kits for outreach | B8: 20000 | C8: same
A9: Registration, CA, e-commerce registration | B9: 20000 | C9: same; adds E-commerce Act listing
A10: Launch marketing (partner onboarding, referral credits) | B10: 20000 | C10: -5,000
A11: Website + instant price calculator (fixed SKUs) | B11: 15000 | C11: +5,000: copy EzPac/Printo self-serve pricing
A12: Delivery setup (3PL account) | B12: 5000 | C12: -5,000
A13: Set-up subtotal | B13: =SUM(B2:B12) -> 215000
A14: Contingency | B14: 50000
A15: Opening operating cash (working capital) | B15: =500000-B13-B14 -> 235000
A16: TOTAL | B16: =B13+B14+B15 -> 500000
A17: Within ceiling? | B17: =IF(B16<=500000,"YES","NO") -> YES
A18: Note: contingency is held outside the operating cash shown in Strategy_Engine; minimum cash < 0 means contingency is being consumed, < -50,000 means the NPR 5L ceiling is breached.

Sheet Strategy_Scenarios
A1: Scenario | B1: Inputs changed (from Strategy base) | C1: Revenue | D1: Contribution | E1: CM % | F1: Op. profit after founder | G1: Min operating cash | H1: Solvent in 5L? | I1: VAT 30L crossed (month)
A2: S0 Strategy base | B2: +50% customers vs 08 Base via starter kit + partner channel; T1 reorder 25%/month | C2: 2334105 | D2: 722200 | E2: 0.309 | F2: 344200 | G2: 203959 | H2: YES | I2: not in 12 mo
A3: S1 Conservative | B3: New-customer multiplier 0.5 (= 08 Base customer count) | C3: 1556070 | D3: 481467 | E3: 0.309 | F3: 103467 | G3: 188897 | H3: YES | I3: not in 12 mo
A4: S2 Stress | B4: Multiplier 0.5; duty 30%; import fixed cost NPR 15,000; T1 price 70; T2 price 125; T1 reorder 15%; T2 reorder 10% | C4: 1291320 | D4: 270590 | E4: 0.21 | F4: -107410 | G4: 71200 | H4: YES | I4: not in 12 mo
A5: S3 Severe | B5: S2 + multiplier 0.35 + founder paid NPR 25,000 from month 4 | C5: 903924 | D5: 189413 | E5: 0.21 | F5: -323587 | G5: -128060 | H5: NO | I5: not in 12 mo
A6: S4 Base + VAT registered | B6: Strategy base with VAT registration; T1/T5 prices cut 8% to absorb 13% VAT for B2C-like buyers | C6: 2258826 | D6: 771196 | E6: 0.341 | F6: 393196 | G6: 209710 | H6: YES | I6: not in 12 mo
A8: Values pasted from LibreOffice recalculation of this workbook with the listed input changes (2026-10-23). Reproduce by editing Inputs / Offer_Ladder.

Sheet Strategy_vs_Base
A1: Metric (12 months) | B1: 08 model v2 Base (pasted) | C1: Strategy (live) | D1: Change | E1: Comment
A2: Revenue | B2: 1983600 | C2: =Strategy_Engine!$B$75 -> 2334104.8 | D2: =C2-B2 -> 350504.83
A3: Contribution | B3: 402223 | C3: =Strategy_Engine!$B$76 -> 722200.46 | D3: =C3-B3 -> 319977.46
A4: Contribution margin % | B4: 0.20277425 | C4: =Strategy_Engine!$B$77 -> 0.30941218 | D4: =C4-B4 -> 0.10663793
A5: Op. profit after founder pay | B5: -77777 | C5: =Strategy_Engine!$B$78 -> 344200.46 | D5: =C5-B5 -> 421977.46
A6: Minimum operating cash (08: opening 235k incl. contingency; strategy: 235k excl. 50k contingency) | B6: -21949 | C6: =Strategy_Engine!$B$79 -> 203959.23 | D6: =C6-B6 -> 225908.23
A7: Paying customers acquired | B7: 44 | C7: =Strategy_Engine!$B$83 -> 66 | D7: =C7-B7 -> 22
A8: Average order value | B8: 26718.75 | C8: =Strategy_Engine!$B$84 -> 16618.038 | D8: =C8-B8 -> -10100.712
A10: Interpretation: the strategy trades a lower average order value for more customers, faster reorders and higher margin per order; see Cost_Levers and Revenue_Levers for the drivers.
A11: Base values pasted from 08_financial_model.xlsx v2 recalculated 2026-10-23; they do not update automatically.

Sheet Cost_Levers
A1: # | B1: Cost lever (what to do) | C1: Driver qty / yr | D1: Saving per unit NPR | E1: Annual saving NPR | F1: Cash/one-off saving NPR | G1: Basis & evidence
A2: C1 | B2: Source short-run cartons from Indian digital printers, pooled monthly | C2: =Strategy_Engine!N16*Offer_Ladder!C3 -> 5452.5 | D2: =Sourcing_Decision!E3-Sourcing_Decision!G3 -> 15.571182 | E2: =IFERROR(C2*D2,0) -> 84901.868 | F2: 0 | G2: India_Benchmarks (Printo ₹33 mono carton, V) vs Nepal offset with NPR 9,000 die/plate (A)
A3: C2 | B3: Gang-run stickers: batch all customers' sticker jobs on shared sheets weekly | C3: =Strategy_Engine!N6*Offer_Ladder!B3 -> 8306.25 | D3: =9-4 -> 5 | E3: =IFERROR(C3*D3,0) -> 41531.25 | F3: 0 | G3: v1 sticker cost NPR 9 @100 vs ~NPR 4 when ganged (A); Indian guide: labels ₹1-10 (S)
A4: C3 | B4: Standard-size library (4-6 sizes): reuse dies on reorders, no new die per customer | C4: =Strategy_Engine!N26*0.5 -> 3.24 | D4: =Offer_Ladder!D8 -> 4000 | E4: =IFERROR(C4*D4,0) -> 12960 | F4: 0 | G4: Indian guide: custom die-cut doubles setup cost; die ₹2,000-8,000 (V). Assumes 50% of bulk orders reuse a die
A5: C4 | B5: Use 3PL last-mile (NPR 70-80) instead of own delivery | C5: =Strategy_Engine!N54 -> 140.4561 | D5: =Inputs!$B$11-Inputs!$B$12 -> 520 | E5: =IFERROR(C5*D5,0) -> 73037.171 | F5: 0 | G5: Kathmandu Post 27 Aug 2026 (S)
A6: C5 | B6: Home office until 15 active customers (defer rent and deposit) | C6: 4 | D6: 8000 | E6: =IFERROR(C6*D6,0) -> 32000 | F6: 25000 | G6: Capital_Plan
A7: C6 | B7: Voluntary VAT registration (recover supplier/import VAT) - only if most customers are VAT-registered businesses | C7: =(Strategy_Engine!N58)*0.6 -> 967142.62 | D7: =Inputs!$B$6*Inputs!$B$8 -> 0.078 | E7: =IFERROR(C7*D7,0) -> 75437.124 | F7: 0 | G7: Leakage = 13% x VAT-billed share (A). Trade-off: must add 13% to prices
A8: C7 | B8: Design templates per segment (bakery, skincare, boutique): cut design hours 3 -> 1 per order | C8: =Strategy_Engine!N54 -> 140.4561 | D8: =2*Inputs!$B$21 -> 800 | E8: =IFERROR(C8*D8,0) -> 112364.88 | F8: 0 | G8: Founder time value (A)
A9: C8 | B9: Off-peak bulk buying of standard stock (Jan-Mar) - 5% lower stock cost | C9: =Strategy_Engine!N6*Offer_Ladder!B3+Strategy_Engine!N46*Offer_Ladder!F3 -> 12256.08 | D9: =0.05*35 -> 1.75 | E9: =IFERROR(C9*D9,0) -> 21448.139 | F9: 0 | G9: Indian guide: order Jan-Mar when printers have capacity (V). 5% is A
A10: C9 | B10: Deposit pass-through: 50% customer deposit funds supplier deposit (working capital freed) | E10: =IFERROR(C10*D10,0) -> 0 | F10: =0.5*Strategy_Engine!E27 -> 21225 | G10: Policy; shown as cash timing benefit for a T3 month
B11: TOTAL | E11: =SUM(E2:E10) -> 453680.43 | F11: =SUM(F2:F10) -> 21225
B13: C1-C4 and C8 are already embedded in Offer_Ladder/Strategy_Engine costs; this sheet shows how much each contributes. C6 is NOT applied in the engine (vat_reg = 0).

Sheet Revenue_Levers
A1: # | B1: Revenue lever (what to do) | C1: Extra orders / yr | D1: Revenue per order NPR | E1: Margin % | F1: Annual contribution NPR | G1: Cost to run / yr | H1: Net gain NPR | I1: Basis
A2: R1 | B2: Bundle upsell: sticker + tissue + thank-you card + bag on every box order (+15% AOV on 40% of orders) | C2: =0.4*Strategy_Engine!N54 -> 56.18244 | D2: =0.15*Strategy_Engine!B84 -> 2492.7057 | E2: 0.55 | F2: =C2*D2*E2 -> 77025.459 | G2: 0 | H2: =F2-G2 -> 77025.459 | I2: Printo/EzPac sell accessories; margin A
A3: R2 | B3: Reorder automation: WhatsApp reminders at 45/75 days, saved dielines (+5 pts monthly reorder on T1-T3) | C3: =0.05*SUM(Strategy_Engine!B3:M3)*6 -> 12.375 | D3: =Offer_Ladder!B10 -> 9500 | E3: =Offer_Ladder!B15 -> 0.39904947 | F3: =C3*D3*E3 -> 46913.254 | G3: 3000 | H3: =F3-G3 -> 43913.254 | I3: A
A4: R3 | B4: Logistics-partner channel: co-offer to Nepal Can Move (1,000+ merchants) & Pathao Commerce (600+) sellers; 1% convert | C4: =1600*0.01*3 -> 48 | D4: =Offer_Ladder!B10 -> 9500 | E4: =Offer_Ladder!B15 -> 0.39904947 | F4: =C4*D4*E4 -> 181966.56 | G4: 10000 | H4: =F4-G4 -> 171966.56 | I4: Merchant counts: Kathmandu Post 27 Aug 2026 (S); conversion & orders A
A5: R4 | B5: Design-only packages for brands that print elsewhere | C5: 6 | D5: =Offer_Ladder!E10 -> 8000 | E5: =Offer_Ladder!E15 -> 0.805 | F5: =C5*D5*E5 -> 38640 | G5: 0 | H5: =F5-G5 -> 38640 | I5: High-margin, zero inventory; A
A6: R5 | B6: Festival & wedding gifting campaign (Dashain-Tihar, Mangsir-Falgun weddings): rigid/gift boxes for corporates | C6: 8 | D6: 40000 | E6: 0.22 | F6: =C6*D6*E6 -> 70400 | G6: 15000 | H6: =F6-G6 -> 55400 | I6: Rigid box economics from 07; A
A7: R6 | B7: Packaging subscription (hold stock, monthly drops) for top 10% customers | C7: =4*6 -> 24 | D7: =Offer_Ladder!F10 -> 21000 | E7: =Offer_Ladder!F15 -> 0.26326248 | F7: =C7*D7*E7 -> 132684.29 | G7: 0 | H7: =F7-G7 -> 132684.29 | I7: Already in engine T5; shown for attribution
A8: R7 | B8: Referral credit 5% for both sides | C8: 12 | D8: =Offer_Ladder!C10 -> 30000 | E8: =Offer_Ladder!C15-0.05 -> 0.27716665 | F8: =C8*D8*E8 -> 99779.993 | G8: 0 | H8: =F8-G8 -> 99779.993 | I8: A
A9: R8 | B9: Export/handicraft premium packaging (Lokta, private label) like Prime Felt & Agro | C9: 3 | D9: 50000 | E9: 0.25 | F9: =C9*D9*E9 -> 37500 | G9: 5000 | H9: =F9-G9 -> 32500 | I9: PFA offers in-house design + manufacturing partner + private label (V)
A10: R9 | B10: Fixed-SKU online catalogue with instant prices (EzPac/Printo model) on own site + Daraz | C10: =0.2*Strategy_Engine!N6 -> 16.6125 | D10: =Offer_Ladder!B10 -> 9500 | E10: =Offer_Ladder!B15 -> 0.39904947 | F10: =C10*D10*E10 -> 62977.489 | G10: 6000 | H10: =F10-G10 -> 56977.489 | I10: EzPac live price calculator (V); 20% lift is A
B11: TOTAL (R1-R5, R7-R9 are upside NOT in Strategy_Engine; R6 is already in it) | H11: =SUM(H2:H10)-H7 -> 576202.76

Sheet Label_Printer_BE
A1: Item | B1: Value | C1: Basis
A2: Epson ColorWorks C4050 advertised price (INR) | B2: 152500 | C2: IndiaMART listing, New Delhi (S)
A3: Converted NPR | B3: =B2*Inputs!$B$2/100 -> 244228.75
A4: Landed multiplier (freight 5%, duty 10% A, VAT if unregistered) | B4: =1.05*1.1*(1+IF(Inputs!$B$7=1,0,Inputs!$B$6)) -> 1.30515 | C4: UNVERIFIED duty
A5: Landed cost NPR | B5: =B3*B4 -> 318755.15
A6: Add: cutter for die-cut shapes (sticker half-cutter, landed est.) | B6: 230216 | C6: Machinery sheet 08 (S/A)
A7: Total investment NPR | B7: =B5+B6 -> 548971.15
A8: Outsourced cost per 50mm label NPR (gang-run) | B8: 4 | C8: Cost_Levers C2 (A)
A9: In-house media+ink cost per label NPR | B9: 1.5 | C9: A - get Epson ink/media quote
A10: Operator time per label NPR | B10: 0.4 | C10: A
A11: Saving per label NPR | B11: =B8-B9-B10 -> 2.1
A12: Labels needed to recover investment | B12: =B7/B11 -> 261414.83
A13: Labels per year in Strategy_Engine (T1 kits x 100) | B13: =Strategy_Engine!N6*Offer_Ladder!B3 -> 8306.25
A14: Years to payback at strategy volume | B14: =B12/B13 -> 31.472064
A15: Decision | B15: =IF(B14<=1.5,"Consider after pilot gate","Do NOT buy: payback too long - keep outsourcing") -> Do NOT buy: payback too long - keep outsourcing | C15: Rule: buy only if payback <= 18 months on proven volume

Sheet Competitor_Matrix
A1: Competitor | B1: Country | C1: Low MOQ | D1: Design service | E1: Price transparency | F1: Speed | G1: Range | H1: Premium finish | I1: Valley presence | J1: Total /21 | K1: What to COPY | L1: How WE beat them | M1: Evidence
A2: The Box House Nepal | B2: Nepal | C2: 2 | D2: 0 | E2: 3 | F2: 2 | G2: 1 | H2: 0 | I2: 3 | J2: =SUM(C2:I2) -> 11 | K2: Online price list with visible prices; pack-of-50 stock boxes | L2: Add custom branding (stickers/sleeves) on stock boxes; design included | M2: V
A3: Atlas Packaging | B3: Nepal | C3: 1 | D3: 1 | E3: 0 | F3: 1 | G3: 1 | H3: 1 | I3: 3 | J3: =SUM(C3:I3) -> 8 | K3: Bakery specialisation; custom printed cake boxes | L3: Smaller runs + sample-first for new bakeries | M3: S
A4: Prime Felt & Agro (PFA) | B4: Nepal | C4: 1 | D4: 2 | E4: 1 | F4: 2 | G4: 2 | H4: 1 | I4: 2 | J4: =SUM(C4:I4) -> 11 | K4: In-house design + manufacturing partner + private label; sample packs; 24h quote promise | L4: Focus on local brands not export; faster local turnaround | M4: V
A5: Packaging Product (Lazimpat) | B5: Nepal | C5: 1 | D5: 2 | E5: 0 | F5: 1 | G5: 2 | H5: 1 | I5: 3 | J5: =SUM(C5:I5) -> 10 | K5: Custom packaging and design services (directory) | L5: Transparent tiered pricing, starter kits | M5: S
A6: Global Packaging / Ace / Modern / Shree Ganapati | B6: Nepal | C6: 0 | D6: 0 | E6: 0 | F6: 1 | G6: 2 | H6: 0 | I6: 3 | J6: =SUM(C6:I6) -> 6 | K6: Corrugated capacity - use as T3 suppliers | L6: Partner, not fight: we bring them small brands | M6: S
A7: Chandika Print Pack | B7: Nepal | C7: 0 | D7: 0 | E7: 0 | F7: 1 | G7: 1 | H7: 1 | I7: 3 | J7: =SUM(C7:I7) -> 6 | K7: Industrial flexible packaging | L7: Not a target segment | M7: S
A8: Handmade-paper makers (Mahaguthi, Nepali Paper Products) | B8: Nepal | C8: 1 | D8: 0 | E8: 0 | F8: 1 | G8: 1 | H8: 2 | I8: 3 | J8: =SUM(C8:I8) -> 8 | K8: Lokta premium look; free samples | L8: Use as premium supplier for gifting tier | M8: S
A9: Printo | B9: India | C9: 3 | D9: 1 | E9: 3 | F9: 2 | G9: 3 | H9: 2 | I9: 0 | J9: =SUM(C9:I9) -> 14 | K9: Fixed SKUs, instant pricing, sticker-embellished mailers, express tier | L9: Local delivery, NPR pricing, no import hassle for customer | M9: V
A10: EzPac | B10: India | C10: 3 | D10: 2 | E10: 3 | F10: 2 | G10: 2 | H10: 1 | I10: 0 | J10: =SUM(C10:I10) -> 13 | K10: 10-unit MOQ, self-serve design, live price calculator | L10: Hands-on local design & sampling | M10: V
A11: Diva Design (Ahmedabad) | B11: India | C11: 3 | D11: 2 | E11: 1 | F11: 2 | G11: 1 | H11: 1 | I11: 0 | J11: =SUM(C11:I11) -> 10 | K11: No-minimum sticker/label press built against 500 MOQ norm | L11: Local equivalent for Nepal | M11: S
A12: IndiaMART small vendors (e.g., Mahalaxmi kraft bags ₹15@500) | B12: India | C12: 1 | D12: 0 | E12: 2 | F12: 1 | G12: 2 | H12: 0 | I12: 0 | J12: =SUM(C12:I12) -> 6 | K12: Low unit prices - benchmark ceiling | L12: Customer can't easily import small lots; we can consolidate | M12: S
A14: OUR TARGET POSITION | B14: Nepal | C14: 3 | D14: 3 | E14: 3 | F14: 2 | G14: 2 | H14: 1 | I14: 3 | J14: =SUM(C14:I14) -> 17 | K14: Combine Printo/EzPac service model with Nepal presence | L14: White space: no Valley player found combining low MOQ + design + transparent pricing
A15: Scores 0-3 are analyst judgements from limited evidence (V/S column); treat as hypotheses to validate by mystery-shopping 5 competitors.

Sheet Priority_Matrix
A1: # | B1: Initiative | C1: Impact 1-10 | D1: Confidence 1-10 | E1: Ease 1-10 | F1: ICE score | G1: Rank | H1: When
A2: P1 | B2: Launch T1 Brand Starter Kit (stock box + custom sticker) with fixed prices | C2: 8 | D2: 6 | E2: 9 | F2: =C2*D2*E2 -> 432 | G2: =RANK(F2,$F$2:$F$15) -> 2 | H2: Week 1-4
A3: P2 | B3: Get 3 Nepal quotes + 1 Indian digital quote per product; verify HS 4819 duty with clearing agent | C3: 9 | D3: 9 | E3: 8 | F3: =C3*D3*E3 -> 648 | G3: =RANK(F3,$F$2:$F$15) -> 1 | H3: Week 1-2
A4: P3 | B4: Partner with Nepal Can Move / Pathao Commerce for merchant introductions | C4: 8 | D4: 4 | E4: 6 | F4: =C4*D4*E4 -> 192 | G4: =RANK(F4,$F$2:$F$15) -> 9 | H4: Week 3-8
A5: P4 | B5: Standard-size library (4-6 sizes) and segment design templates | C5: 7 | D5: 7 | E5: 8 | F5: =C5*D5*E5 -> 392 | G5: =RANK(F5,$F$2:$F$15) -> 3 | H5: Week 2-6
A6: P5 | B6: Monthly consolidated India import for short-run cartons | C6: 7 | D6: 4 | E6: 5 | F6: =C6*D6*E6 -> 140 | G6: =RANK(F6,$F$2:$F$15) -> 11 | H6: Month 2-3 (after duty verified)
A7: P6 | B7: Gang-run sticker batching with one local digital printer | C7: 6 | D7: 6 | E7: 8 | F7: =C7*D7*E7 -> 288 | G7: =RANK(F7,$F$2:$F$15) -> 6 | H7: Week 3-6
A8: P7 | B8: Instant price calculator / fixed-SKU catalogue on website | C8: 6 | D8: 6 | E8: 6 | F8: =C8*D8*E8 -> 216 | G8: =RANK(F8,$F$2:$F$15) -> 7 | H8: Month 2
A9: P8 | B9: Design-only packages | C9: 5 | D9: 7 | E9: 9 | F9: =C9*D9*E9 -> 315 | G9: =RANK(F9,$F$2:$F$15) -> 5 | H9: Week 1
A10: P9 | B10: Reorder automation (WhatsApp reminders, saved files) | C10: 6 | D10: 7 | E10: 9 | F10: =C10*D10*E10 -> 378 | G10: =RANK(F10,$F$2:$F$15) -> 4 | H10: From first order
A11: P10 | B11: Festival/wedding gifting campaign | C11: 7 | D11: 5 | E11: 6 | F11: =C11*D11*E11 -> 210 | G11: =RANK(F11,$F$2:$F$15) -> 8 | H11: 6-8 weeks before Dashain/Tihar & Mangsir
A12: P11 | B12: Packaging subscription for top customers | C12: 6 | D12: 4 | E12: 5 | F12: =C12*D12*E12 -> 120 | G12: =RANK(F12,$F$2:$F$15) -> 12 | H12: Month 4+
A13: P12 | B13: Voluntary VAT registration (if B2B customers are VAT-registered) | C13: 5 | D13: 5 | E13: 7 | F13: =C13*D13*E13 -> 175 | G13: =RANK(F13,$F$2:$F$15) -> 10 | H13: Decide with CA, Week 1
... A15: P14 | B15: Rent premises | C15: 2 | D15: 8 | E15: 7 | F15: =C15*D15*E15 -> 112 | G15: =RANK(F15,$F$2:$F$15) -> 13 | H15: After 15 active customers

Sheet KPI_Targets
A1: KPI | B1: Day 30 | C1: Day 60 | D1: Day 90 | E1: Stop / change trigger
A2: Verified prospects listed | B2: 150 | C2: 250 | D2: 350 | E2: <100 by day 30
A3: Outreach contacts (cumulative) | B3: 60 | C3: 140 | D3: 240 | E3: <50% of target 3 weeks running
A4: Quote requests (cumulative) | B4: 8 | C4: 20 | D4: 35 | E4: 0 in any 3-week window
A5: Paying customers (cumulative) | B5: 2 | C5: 6 | D5: 12 | E5: <4 by day 90 -> stop
A6: Billed revenue NPR (cumulative) | B6: 15000 | C6: 60000 | D6: 130000 | E6: <50,000 by day 90 -> stop
A7: Blended gross margin | B7: 0.35 | C7: 0.35 | D7: 0.35 | E7: <25% -> change; <15% -> stop
A8: Contribution per order NPR | B8: 3000 | C8: 3000 | D8: 3000 | E8: 2 orders in a row below -> re-price
A9: Reorder rate (customers with 2+ orders) | B9: 0 | C9: 0.15 | D9: 0.25 | E9: <10% by day 90 -> change offer
A10: On-time delivery | B10: 0.9 | C10: 0.9 | D10: 0.95 | E10: <80% -> change supplier
A11: Cash balance NPR (operating) | B11: 200000 | C11: 170000 | D11: 150000 | E11: <100,000 -> freeze spend

Sheet Checks
A1: Check | B1: Result
A2: Capital plan totals NPR 5,00,000 | B2: =IF(Capital_Plan!B16=500000,"OK","ERROR") -> OK
A3: Opening operating cash positive | B3: =IF(Capital_Plan!B15>0,"OK","ERROR") -> OK
A4: Strategy revenue = sum of tier revenues | B4: =IF(ABS(Strategy_Engine!N55-(Strategy_Engine!N7+Strategy_Engine!N17+Strategy_Engine!N27+Strategy_Engine!N37+Strategy_Engine!N47))<1,"OK","ERROR") -> OK
A5: Closing cash M12 = opening + sum net cash flow | B5: =IF(ABS(Strategy_Engine!M72-(Capital_Plan!B15+Strategy_Engine!N71))<1,"OK","ERROR") -> OK
A6: All tier gross margins between 0 and 100% | B6: =IF(AND(MIN(Offer_Ladder!B12:F12)>0,MAX(Offer_Ladder!B12:F12)<1),"OK","ERROR") -> OK
